print("Traceback (most recent call last):\n  File \"/tmp/ansible_create_database_node_payload_4rb2_v20/ansible_create_database_node_payload.zip/ansible/modules/create_database_node.py\", line 254, in main\n  File \"/tmp/ansible_create_database_node_payload_4rb2_v20/ansible_create_database_node_payload.zip/ansible/modules/create_database_node.py\", line 178, in manage_states\n  File \"/tmp/ansible_create_database_node_payload_4rb2_v20/ansible_create_database_node_payload.zip/ansible/modules/create_database_node.py\", line 204, in create_vm\n  File \"/tmp/ansible_create_database_node_payload_4rb2_v20/ansible_create_database_node_payload.zip/ansible/module_utils/create_opensearch.py\", line 20, in create_vm\n  File \"/tmp/ansible_create_database_node_payload_4rb2_v20/ansible_create_database_node_payload.zip/ansible/module_utils/create_opensearch.py\", line 39, in write_payload_to_file\n  File \"/tmp/ansible_create_database_node_payload_4rb2_v20/ansible_create_database_node_payload.zip/ansible/module_utils/get_vapp_vm_template.py\", line 19, in get_vapp_vm_template_href\n  File \"/tmp/ansible_create_database_node_payload_4rb2_v20/ansible_create_database_node_payload.zip/ansible/module_utils/get_vapp_vm_template.py\", line 13, in handle_get\nException: b'<?xml version=\"1.0\" encoding=\"UTF-8\" standalone=\"yes\"?>\\n<Error xmlns=\"http://www.vmware.com/vcloud/v1.5\" xmlns:vmext=\"http://www.vmware.com/vcloud/extension/v1.5\" xmlns:ovf=\"http://schemas.dmtf.org/ovf/envelope/1\" xmlns:vssd=\"http://schemas.dmtf.org/wbem/wscim/1/cim-schema/2/CIM_VirtualSystemSettingData\" xmlns:common=\"http://schemas.dmtf.org/wbem/wscim/1/common\" xmlns:rasd=\"http://schemas.dmtf.org/wbem/wscim/1/cim-schema/2/CIM_ResourceAllocationSettingData\" xmlns:vmw=\"http://www.vmware.com/schema/ovf\" xmlns:ovfenv=\"http://schemas.dmtf.org/ovf/environment/1\" xmlns:ns9=\"http://www.vmware.com/vcloud/versions\" message=\"Bad request: Expression \\'container==\\' is not a comparison expression.\" majorErrorCode=\"400\" minorErrorCode=\"BAD_REQUEST\"/>\\n'\n\nDuring handling of the above exception, another exception occurred:\n\nTraceback (most recent call last):\n  File \"/root/.ansible/tmp/ansible-tmp-1720523874.5767133-80-150677425355939/AnsiballZ_create_database_node.py\", line 107, in <module>\n    _ansiballz_main()\n  File \"/root/.ansible/tmp/ansible-tmp-1720523874.5767133-80-150677425355939/AnsiballZ_create_database_node.py\", line 99, in _ansiballz_main\n    invoke_module(zipped_mod, temp_path, ANSIBALLZ_PARAMS)\n  File \"/root/.ansible/tmp/ansible-tmp-1720523874.5767133-80-150677425355939/AnsiballZ_create_database_node.py\", line 47, in invoke_module\n    runpy.run_module(mod_name='ansible.modules.create_database_node', init_globals=dict(_module_fqn='ansible.modules.create_database_node', _modlib_path=modlib_path),\n  File \"/usr/lib64/python3.8/runpy.py\", line 207, in run_module\n    return _run_module_code(code, init_globals, run_name, mod_spec)\n  File \"/usr/lib64/python3.8/runpy.py\", line 97, in _run_module_code\n    _run_code(code, mod_globals, init_globals,\n  File \"/usr/lib64/python3.8/runpy.py\", line 87, in _run_code\n    exec(code, run_globals)\n  File \"/tmp/ansible_create_database_node_payload_4rb2_v20/ansible_create_database_node_payload.zip/ansible/modules/create_database_node.py\", line 266, in <module>\n  File \"/tmp/ansible_create_database_node_payload_4rb2_v20/ansible_create_database_node_payload.zip/ansible/modules/create_database_node.py\", line 261, in main\n  File \"/tmp/ansible_create_database_node_payload_4rb2_v20/ansible_create_database_node_payload.zip/ansible/module_utils/basic.py\", line 1538, in fail_json\n  File \"/tmp/ansible_create_database_node_payload_4rb2_v20/ansible_create_database_node_payload.zip/ansible/module_utils/basic.py\", line 1511, in _return_formatted\n  File \"/tmp/ansible_create_database_node_payload_4rb2_v20/ansible_create_database_node_payload.zip/ansible/module_utils/common/parameters.py\", line 890, in remove_values\n  File \"/tmp/ansible_create_database_node_payload_4rb2_v20/ansible_create_database_node_payload.zip/ansible/module_utils/common/parameters.py\", line 461, in _remove_values_conditions\nTypeError: Value of unknown type: <class 'Exception'>, b'<?xml version=\"1.0\" encoding=\"UTF-8\" standalone=\"yes\"?>\\n<Error xmlns=\"http://www.vmware.com/vcloud/v1.5\" xmlns:vmext=\"http://www.vmware.com/vcloud/extension/v1.5\" xmlns:ovf=\"http://schemas.dmtf.org/ovf/envelope/1\" xmlns:vssd=\"http://schemas.dmtf.org/wbem/wscim/1/cim-schema/2/CIM_VirtualSystemSettingData\" xmlns:common=\"http://schemas.dmtf.org/wbem/wscim/1/common\" xmlns:rasd=\"http://schemas.dmtf.org/wbem/wscim/1/cim-schema/2/CIM_ResourceAllocationSettingData\" xmlns:vmw=\"http://www.vmware.com/schema/ovf\" xmlns:ovfenv=\"http://schemas.dmtf.org/ovf/environment/1\" xmlns:ns9=\"http://www.vmware.com/vcloud/versions\" message=\"Bad request: Expression \\'container==\\' is not a comparison expression.\" majorErrorCode=\"400\" minorErrorCode=\"BAD_REQUEST\"/>\\n'\n")